Workbook

Sheet base-pim_spbrasil
A1: UF | B1: indice_pim_sem_ajuste | C1: indice_pim _com_ajuste_sazonal | D1: Segmentação | E1: Date | F1: DIA | G1: MÊS | H1: ANOS
A2: Brasil | B2: 103.35733 | C2: 114.03353 | D2: Indústria geral | E2: 40909 | F2: =DAY(E2) -> 1 | G2: JANEIRO | H2: =YEAR(E2) -> 2012
A3: Brasil | B3: 99.38515 | C3: 100.17024 | D3: Indústrias extrativas | E3: 44986 | F3: 3 | G3: MARÇO | H3: =YEAR(E3) -> 2023
A4: Brasil | B4: 102.50798 | C4: 101.28033 | D4: Indústrias de transformação | E4: 43770 | F4: 11 | G4: NOVEMBRO | H4: =YEAR(E4) -> 2019
A5: Brasil | B5: 113.06392 | C5: 103.60741 | D5: Metalurgia | E5: 43739 | F5: 10 | G5: OUTUBRO | H5: =YEAR(E5) -> 2019
A6: Brasil | B6: 92.03653 | C6: 99.635471 | D6: Fabricação de produtos alimentícios | E6: 45017 | F6: 4 | G6: ABRIL | H6: =YEAR(E6) -> 2023
A7: Brasil | B7: 127.32526 | C7: 115.58534 | D7: Fabricação de bebidas | E7: 41913 | F7: 10 | G7: OUTUBRO | H7: =YEAR(E7) -> 2014
A8: Brasil | B8: 102.62008 | C8: 116.36117 | D8: Fabricação de produtos têxteis | E8: 41306 | F8: 2 | G8: FEVEREIRO | H8: =YEAR(E8) -> 2013
A9: Brasil | B9: 106.94489 | C9: 101.70359 | D9: Confecção de artigos do vestuário e acessórios | E9: 43709 | F9: 9 | G9: SETEMBRO | H9: =YEAR(E9) -> 2019
A10: Brasil | B10: 104.73802 | C10: 100.69178 | D10: Fabricação de celulose, papel e produtos de papel | E10: 45047 | F10: 5 | G10: MAIO | H10: =YEAR(E10) -> 2023
A11: Brasil | B11: 112.1134 | C11: 101.41884 | D11: Fabricação de coque, de produtos derivados do petróleo e de biocombustíveis | E11: 43678 | F11: 8 | G11: AGOSTO | H11: =YEAR(E11) -> 2019
A12: Brasil | B12: 123.07107 | C12: 115.35997 | D12: Fabricação de produtos químicos | E12: 41883 | F12: 9 | G12: SETEMBRO | H12: =YEAR(E12) -> 2014
A13: Brasil | B13: 116.2884 | C13: 114.98631 | D13: Fabricação de produtos farmoquímicos e farmacêuticos | E13: 41944 | F13: 11 | G13: NOVEMBRO | H13: =YEAR(E13) -> 2014
A14: Brasil | B14: 89.65106 | C14: 99.172114 | D14: Fabricação de produtos de borracha e de material plástico | E14: 43800 | H14: =YEAR(E14) -> 2019
A15: Brasil | B15: 118.65181 | C15: 120.01087 | D15: Fabricação de produtos de minerais não metálicos | E15: 41365 | H15: =YEAR(E15) -> 2013
A16: Brasil | B16: 91.95129 | C16: 99.780228 | D16: Fabricação de produtos de metal, exceto máquinas e equipamentos | E16: 44896 | H16: =YEAR(E16) -> 2022
A17: Brasil | B17: 90.76051 | C17: 93.292351 | D17: Fabricação de equipamentos de informática, produtos eletrônicos e ópticos | E17: 43891
A18: Brasil | B18: 90.3957 | C18: 99.490153 | D18: Fabricação de máquinas, aparelhos e materiais elétricos | E18: 44927
A19: Brasil | B19: 91.90105 | C19: 101.40686 | D19: Fabricação de máquinas e equipamentos | E19: 43862
A20: Brasil | B20: 123.92138 | C20: 115.14627 | D20: Fabricação de veículos automotores, reboques e carrocerias | E20: 41852
A21: Brasil | B21: 93.25265 | C21: 101.1623 | D21: Fabricação de outros equipamentos de transporte, exceto veículos automotores | E21: 43831
A22: Brasil | B22: 113.85214 | C22: 117.99253 | E22: 41334
A23: Brasil | B23: 87.42669 | C23: 99.716061 | E23: 44958
A24: Brasil | B24: 121.70206 | C24: 114.42635 | E24: 41821
A25: Brasil | B25: 101.88765 | C25: 100.20323 | E25: 45078
A26: Brasil | B26: 104.56847 | C26: 98.7005 | E26: 44470
A27: Brasil | B27: 106.2818 | C27: 99.85848 | E27: 45170
A28: Brasil | B28: 94.02286 | C28: 101.69914 | E28: 43466
A29: Brasil | B29: 97.57125 | C29: 110.84776 | E29: 42036
A30: Brasil | B30: 107.01406 | C30: 100.02346 | E30: 45200
A31: Brasil | B31: 122.16077 | C31: 117.2382 | E31: 41214
A32: Brasil | B32: 90.84141 | C32: 101.73098 | E32: 43435
A33: Brasil | B33: 104.28134 | C33: 102.17156 | E33: 43405
... A165: Brasil | B165: 105.73437 | C165: 101.22079 | E165: 43344
A166: Brasil | B166: 116.90938 | C166: 113.22661
A167: Brasil | B167: 92.44812 | C167: 105.67978
A168: Brasil | B168: 128.08446 | C168: 127.8213
A169: Brasil | B169: 124.45172 | C169: 125.41849
A170: Brasil | B170: 96.49411 | C170: 101.22148
A171: Brasil | B171: 86.65218 | C171: 101.09513
...

Sheet Planilha1
B1: NUM_MÊS | C1: MÊS | E1: ANO
B2: 1 | C2: janeiro | E2: =YEAR('base-pim_spbrasil'!E2) -> 2012
B3: 2 | C3: fevereiro | E3: =YEAR('base-pim_spbrasil'!E3) -> 2023
B4: 3 | C4: março | E4: =YEAR('base-pim_spbrasil'!E4) -> 2019
B5: 4 | C5: abril | E5: =YEAR('base-pim_spbrasil'!E5) -> 2019
B6: 5 | C6: MAIO | E6: =YEAR('base-pim_spbrasil'!E6) -> 2023
B7: 8 | C7: AGOSTO
B8: 9 | C8: SETEMBRO | E8: =YEAR('base-pim_spbrasil'!E8) -> 2013
B9: 10 | C9: OUTUBRO | E9: =YEAR('base-pim_spbrasil'!E9) -> 2019
B10: 11 | C10: NOVEMBRO | E10: =YEAR('base-pim_spbrasil'!E10) -> 2023
E11: =YEAR('base-pim_spbrasil'!E11) -> 2019
E12: =YEAR('base-pim_spbrasil'!E12) -> 2014
E13: =YEAR('base-pim_spbrasil'!E13) -> 2014
E14: =YEAR('base-pim_spbrasil'!E14) -> 2019
E15: =YEAR('base-pim_spbrasil'!E15) -> 2013
E16: =YEAR('base-pim_spbrasil'!E16) -> 2022
